<?xml version="1.0"?>

<robot xmlns:xacro="http://www.ros.org/wiki/xacro">

  <!-- Wheel dimensions -->
  <xacro:property name="wheel_radius" value="0.06"/>
  <xacro:property name="wheel_width" value="0.03"/>

  <!-- Wheel macro -->
  <xacro:macro name="wheel" params="name x y">

    <link name="${name}_wheel">

      <visual>
        <origin xyz="0 0 0" rpy="1.5708 0 0"/>
        <geometry>
          <cylinder radius="${wheel_radius}"
                    length="${wheel_width}"/>
        </geometry>
        <material name="black"/>
      </visual>

      <collision>
        <origin xyz="0 0 0" rpy="1.5708 0 0"/>
        <geometry>
          <cylinder radius="${wheel_radius}"
                    length="${wheel_width}"/>
        </geometry>
      </collision>

      <inertial>
        <mass value="0.5"/>

        <origin xyz="0 0 0"/>

        <inertia
            ixx="0.001"
            ixy="0"
            ixz="0"
            iyy="0.001"
            iyz="0"
            izz="0.001"/>
      </inertial>

    </link>

    <joint name="${name}_wheel_joint" type="continuous">

      <parent link="base_link"/>

      <child link="${name}_wheel"/>

      <!-- Wheel center -->
      <origin xyz="${x} ${y} 0.06"/>

      <!-- Wheel rotates about Y -->
      <axis xyz="0 1 0"/> 
      <dynamics damping="0.1" friction="0.1"/>

    </joint>

  </xacro:macro>

  <!-- Front -->
  <xacro:wheel name="front_left"  x="0.15"  y="0.17"/>
  <xacro:wheel name="front_right" x="0.15"  y="-0.17"/>

  <!-- Rear -->
  <xacro:wheel name="rear_left"   x="-0.15" y="0.17"/>
  <xacro:wheel name="rear_right"  x="-0.15" y="-0.17"/>

</robot>
